<?xml version='1.0' encoding='utf-8'?>
<sdf version="1.7">
    <world name="robot_world">
        <model name="robot_fourW">
            <link name="brw">
                <pose>0.0 0.0 0.0 0.0 -0.0 0.0</pose>
                <inertial>
                    <mass>0.0007891680745817905</mass>
                    <pose>0.034 0.003974860847171141 0.004034690807627012 0.0 0.0 0.0</pose>
                    <inertia>
                        <ixx>6.313344188978208e-09</ixx>
                        <iyy>3.4197285270257323e-09</iyy>
                        <izz>3.4197277116735114e-09</izz>
                        <ixy>0.0</ixy>
                        <iyz>-1.6543612251060553e-24</iyz>
                        <ixz>-1.3234889800848443e-23</ixz>
                    </inertia>
                </inertial>
                <visual name="brw_visual">
                    <geometry>
                        <mesh>
                            <uri>model://robot_fourW/meshes/brw.stl</uri>
                            <scale>0.001 0.001 0.001</scale>
                        </mesh>
                    </geometry>
                </visual>
                <collision name="brw_collision">
                    <geometry>
                        <mesh>
                            <uri>model://robot_fourW/meshes/brw.stl</uri>
                            <scale>0.001 0.001 0.001</scale>
                        </mesh>
                    </geometry>
                </collision>
            </link>
            <link name="base_link">
                <pose>0.0125 -0.002037749325439766 -4.998604814583918e-06 0.0 -0.0 0.0</pose>
                <inertial>
                    <mass>0.02494941699556569</mass>
                    <pose>0.010000253383063153 0.015059584943849494 0.004217585871022689 0.0 0.0 0.0</pose>
                    <inertia>
                        <ixx>1.8593069123257e-06</ixx>
                        <iyy>8.692521306422306e-07</iyy>
                        <izz>2.6006184492381023e-06</izz>
                        <ixy>-9.622031856110452e-11</ixy>
                        <iyz>-6.456019151724861e-10</iyz>
                        <ixz>-6.6673008412653336e-12</ixz>
                    </inertia>
                </inertial>
                <visual name="base_link_visual">
                    <geometry>
                        <mesh>
                            <uri>model://robot_fourW/meshes/base_link.stl</uri>
                            <scale>0.001 0.001 0.001</scale>
                        </mesh>
                    </geometry>
                </visual>
                <collision name="base_link_collision">
                    <geometry>
                        <mesh>
                            <uri>model://robot_fourW/meshes/base_link.stl</uri>
                            <scale>0.001 0.001 0.001</scale>
                        </mesh>
                    </geometry>
                </collision>
            </link>
            <link name="lidar">
                <pose>0.0125 -0.002037749325439766 -4.998604814583363e-06 0.0 -0.0 0.0</pose>
                <inertial>
                    <mass>0.0012330751165340462</mass>
                    <pose>0.010000000148488777 0.015000000223517418 0.009542240059091772 0.0 0.0 0.0</pose>
                    <inertia>
                        <ixx>8.117743024227962e-09</ixx>
                        <iyy>8.117745014833845e-09</iyy>
                        <izz>1.5413437961372473e-08</izz>
                        <ixy>-5.293955920339377e-23</ixy>
                        <iyz>0.0</iyz>
                        <ixz>-5.293955920339377e-23</ixz>
                    </inertia>
                </inertial>
                <visual name="lidar_visual">
                    <geometry>
                        <mesh>
                            <uri>model://robot_fourW/meshes/lidar.stl</uri>
                            <scale>0.001 0.001 0.001</scale>
                        </mesh>
                    </geometry>
                </visual>
                <collision name="lidar_collision">
                    <geometry>
                        <mesh>
                            <uri>model://robot_fourW/meshes/lidar.stl</uri>
                            <scale>0.001 0.001 0.001</scale>
                        </mesh>
                    </geometry>
                </collision>
            </link>
            <link name="flw">
                <pose>0.017542473532670137 -0.007133792047273415 -0.0015422400590917745 0.0 -0.0 0.0</pose>
                <inertial>
                    <mass>0.0007891680745817905</mass>
                    <pose>-0.0065424735326701415 0.02960865289444456 0.005576930866718788 0.0 0.0 0.0</pose>
                    <inertia>
                        <ixx>6.313344188978254e-09</ixx>
                        <iyy>3.419728527025825e-09</iyy>
                        <izz>3.419727711673723e-09</izz>
                        <ixy>-2.6469779601696886e-23</ixy>
                        <iyz>1.3234889800848443e-23</iyz>
                        <ixz>-1.3234889800848443e-23</ixz>
                    </inertia>
                </inertial>
                <visual name="flw_visual">
                    <geometry>
                        <mesh>
                            <uri>model://robot_fourW/meshes/flw.stl</uri>
                            <scale>0.001 0.001 0.001</scale>
                        </mesh>
                    </geometry>
                </visual>
                <collision name="flw_collision">
                    <geometry>
                        <mesh>
                            <uri>model://robot_fourW/meshes/flw.stl</uri>
                            <scale>0.001 0.001 0.001</scale>
                        </mesh>
                    </geometry>
                </collision>
            </link>
            <link name="frw">
                <pose>0.0015424735326701367 0.04386620795272658 -0.0015422400590917745 0.0 -0.0 0.0</pose>
                <inertial>
                    <mass>0.0007891680745817905</mass>
                    <pose>0.03245752646732986 -0.021391347105555437 0.005576930866718787 0.0 0.0 0.0</pose>
                    <inertia>
                        <ixx>6.31334418897836e-09</ixx>
                        <iyy>3.419728527025944e-09</iyy>
                        <izz>3.4197277116736172e-09</izz>
                        <ixy>0.0</ixy>
                        <iyz>1.3234889800848443e-23</iyz>
                        <ixz>2.6469779601696886e-23</ixz>
                    </inertia>
                </inertial>
                <visual name="frw_visual">
                    <geometry>
                        <mesh>
                            <uri>model://robot_fourW/meshes/frw.stl</uri>
                            <scale>0.001 0.001 0.001</scale>
                        </mesh>
                    </geometry>
                </visual>
                <collision name="frw_collision">
                    <geometry>
                        <mesh>
                            <uri>model://robot_fourW/meshes/frw.stl</uri>
                            <scale>0.001 0.001 0.001</scale>
                        </mesh>
                    </geometry>
                </collision>
            </link>
            <link name="blw">
                <pose>0.015542473532670137 0.007366207952726578 -0.0015422400590917745 0.0 -0.0 0.0</pose>
                <inertial>
                    <mass>0.0007891680745817908</mass>
                    <pose>-0.00454247353267014 -0.0033913471055554405 0.005576930866718788 0.0 0.0 0.0</pose>
                    <inertia>
                        <ixx>6.313344188978198e-09</ixx>
                        <iyy>3.4197285270258117e-09</iyy>
                        <izz>3.4197277116736172e-09</izz>
                        <ixy>0.0</ixy>
                        <iyz>-1.6543612251060553e-23</iyz>
                        <ixz>-1.3234889800848443e-23</ixz>
                    </inertia>
                </inertial>
                <visual name="blw_visual">
                    <geometry>
                        <mesh>
                            <uri>model://robot_fourW/meshes/blw.stl</uri>
                            <scale>0.001 0.001 0.001</scale>
                        </mesh>
                    </geometry>
                </visual>
                <collision name="blw_collision">
                    <geometry>
                        <mesh>
                            <uri>model://robot_fourW/meshes/blw.stl</uri>
                            <scale>0.001 0.001 0.001</scale>
                        </mesh>
                    </geometry>
                </collision>
            </link>
            <link name="camera">
                <pose>0.01261127142871171 -0.002037749325439764 1.879399958663375e-05 0.0 -0.0 0.0</pose>
                <inertial>
                    <mass>4.5012174053959215e-06</mass>
                    <pose>0.010019812846095197 0.030680517329393885 0.005248385672069328 0.0 0.0 0.0</pose>
                    <inertia>
                        <ixx>7.183941652729761e-13</ixx>
                        <iyy>1.3692702463027689e-12</iyy>
                        <izz>7.18394342110129e-13</izz>
                        <ixy>0.0</ixy>
                        <iyz>0.0</iyz>
                        <ixz>0.0</ixz>
                    </inertia>
                </inertial>
                <visual name="camera_visual">
                    <geometry>
                        <mesh>
                            <uri>model://robot_fourW/meshes/camera.stl</uri>
                            <scale>0.001 0.001 0.001</scale>
                        </mesh>
                    </geometry>
                </visual>
                <collision name="camera_collision">
                    <geometry>
                        <mesh>
                            <uri>model://robot_fourW/meshes/camera.stl</uri>
                            <scale>0.001 0.001 0.001</scale>
                        </mesh>
                    </geometry>
                </collision>
            </link>
            <joint name="base_link_joint_frw" type="revolute">
                <pose>0.03145752646732986 -0.021391207952726584 0.005577240059091775 0.0 0.0 0.0</pose>
                <parent>base_link</parent>
                <child>frw</child>
                <axis>
                    <xyz expressed_in="__model__">1.0 0.0 -0.0</xyz>
                </axis>
            </joint>
            <joint name="base_link_joint_brw" type="revolute">
                <pose>0.033 0.003975 0.004035 0.0 0.0 0.0</pose>
                <parent>base_link</parent>
                <child>brw</child>
                <axis>
                    <xyz expressed_in="__model__">1.0 0.0 -0.0</xyz>
                </axis>
            </joint>
            <joint name="base_link_joint_flw" type="revolute">
                <pose>-0.005542473532670136 0.029608792047273413 0.005577240059091775 0.0 0.0 0.0</pose>
                <parent>base_link</parent>
                <child>flw</child>
                <axis>
                    <xyz expressed_in="__model__">-1.0 0.0 0.0</xyz>
                </axis>
            </joint>
            <joint name="base_link_joint_blw" type="revolute">
                <pose>-0.0035424735326701363 -0.0033912079527265776 0.005577240059091775 0.0 0.0 0.0</pose>
                <parent>base_link</parent>
                <child>blw</child>
                <axis>
                    <xyz expressed_in="__model__">-1.0 0.0 0.0</xyz>
                </axis>
            </joint>
            <joint name="base_link_joint_lidar" type="revolute">
                <pose>0.009999999999999998 0.014999749325439765 0.008541998604814582 0.0 0.0 0.0</pose>
                <parent>base_link</parent>
                <child>lidar</child>
                <axis>
                    <xyz expressed_in="__model__">0.0 0.0 1.0</xyz>
                </axis>
            </joint>
            <joint name="base_link_joint_cam" type="fixed">
                <pose>0.010019728571288288 0.030530749325439765 0.0052482060004133664 0.0 0.0 0.0</pose>
                <parent>base_link</parent>
                <child>camera</child>
            </joint>
        </model>
    </world>
</sdf>